[2022-10-13T22:04:05.226+0000] {taskinstance.py:1165} INFO - Dependencies all met for <TaskInstance: trabalho2.also_run_this manual__2022-10-13T22:04:03.134665+00:00 [queued]>
[2022-10-13T22:04:05.237+0000] {taskinstance.py:1165} INFO - Dependencies all met for <TaskInstance: trabalho2.also_run_this manual__2022-10-13T22:04:03.134665+00:00 [queued]>
[2022-10-13T22:04:05.237+0000] {taskinstance.py:1362} INFO - 
--------------------------------------------------------------------------------
[2022-10-13T22:04:05.237+0000] {taskinstance.py:1363} INFO - Starting attempt 1 of 1
[2022-10-13T22:04:05.237+0000] {taskinstance.py:1364} INFO - 
--------------------------------------------------------------------------------
[2022-10-13T22:04:05.250+0000] {taskinstance.py:1383} INFO - Executing <Task(BashOperator): also_run_this> on 2022-10-13 22:04:03.134665+00:00
[2022-10-13T22:04:05.256+0000] {standard_task_runner.py:54} INFO - Started process 6901 to run task
[2022-10-13T22:04:05.258+0000] {standard_task_runner.py:82} INFO - Running: ['***', 'tasks', 'run', 'trabalho2', 'also_run_this', 'manual__2022-10-13T22:04:03.134665+00:00', '--job-id', '27', '--raw', '--subdir', 'DAGS_FOLDER/***_titanic.py', '--cfg-path', '/tmp/tmpkzuutq8x']
[2022-10-13T22:04:05.259+0000] {standard_task_runner.py:83} INFO - Job 27: Subtask also_run_this
[2022-10-13T22:04:05.260+0000] {dagbag.py:525} INFO - Filling up the DagBag from /opt/***/dags/***_titanic.py
[2022-10-13T22:04:05.616+0000] {logging_mixin.py:117} WARNING - /home/***/.local/lib/python3.7/site-packages/***/models/dag.py:3425 RemovedInAirflow3Warning: Param `schedule_interval` is deprecated and will be removed in a future release. Please use `schedule` instead.
[2022-10-13T22:04:09.815+0000] {task_command.py:384} INFO - Running <TaskInstance: trabalho2.also_run_this manual__2022-10-13T22:04:03.134665+00:00 [running]> on host 708a74060eb9
[2022-10-13T22:04:09.899+0000] {taskinstance.py:1592} INFO - Exporting the following env vars:
AIRFLOW_CTX_DAG_OWNER=Marcos Vieira
AIRFLOW_CTX_DAG_ID=trabalho2
AIRFLOW_CTX_TASK_ID=also_run_this
AIRFLOW_CTX_EXECUTION_DATE=2022-10-13T22:04:03.134665+00:00
AIRFLOW_CTX_TRY_NUMBER=1
AIRFLOW_CTX_DAG_RUN_ID=manual__2022-10-13T22:04:03.134665+00:00
[2022-10-13T22:04:09.900+0000] {subprocess.py:63} INFO - Tmp dir root location: 
 /tmp
[2022-10-13T22:04:09.900+0000] {subprocess.py:75} INFO - Running command: ['/bin/bash', '-c', 'curl -L -o/opt/storage_data/data/titanic.csv https://raw.githubusercontent.com/neylsoncrepalde/titanic_data_with_semicolon/main/titanic.csv']
[2022-10-13T22:04:09.906+0000] {clientserver.py:543} INFO - Closing down clientserver connection
[2022-10-13T22:04:09.913+0000] {subprocess.py:86} INFO - Output:
[2022-10-13T22:04:09.919+0000] {subprocess.py:93} INFO -   % Total    % Received % Xferd  Average Speed   Time    Time     Time  Current
[2022-10-13T22:04:09.920+0000] {subprocess.py:93} INFO -                                  Dload  Upload   Total   Spent    Left  Speed
[2022-10-13T22:04:10.167+0000] {clientserver.py:505} INFO - Error while sending or receiving.
Traceback (most recent call last):
  File "/home/airflow/.local/lib/python3.7/site-packages/py4j/clientserver.py", line 503, in send_command
    self.socket.sendall(command.encode("utf-8"))
ConnectionResetError: [Errno 104] Connection reset by peer
[2022-10-13T22:04:10.171+0000] {clientserver.py:543} INFO - Closing down clientserver connection
[2022-10-13T22:04:10.171+0000] {java_gateway.py:1052} INFO - Exception while sending command.
Traceback (most recent call last):
  File "/home/airflow/.local/lib/python3.7/site-packages/py4j/clientserver.py", line 503, in send_command
    self.socket.sendall(command.encode("utf-8"))
ConnectionResetError: [Errno 104] Connection reset by peer

During handling of the above exception, another exception occurred:

Traceback (most recent call last):
  File "/home/airflow/.local/lib/python3.7/site-packages/py4j/java_gateway.py", line 1038, in send_command
    response = connection.send_command(command)
  File "/home/airflow/.local/lib/python3.7/site-packages/py4j/clientserver.py", line 507, in send_command
    "Error while sending", e, proto.ERROR_ON_SEND)
py4j.protocol.Py4JNetworkError: Error while sending
[2022-10-13T22:04:10.175+0000] {clientserver.py:543} INFO - Closing down clientserver connection
[2022-10-13T22:04:10.195+0000] {subprocess.py:93} INFO -   0     0    0     0    0     0      0      0 --:--:-- --:--:-- --:--:--     0100 60326  100 60326    0     0   214k      0 --:--:-- --:--:-- --:--:--  214k
[2022-10-13T22:04:10.197+0000] {subprocess.py:97} INFO - Command exited with return code 0
[2022-10-13T22:04:10.233+0000] {taskinstance.py:1406} INFO - Marking task as SUCCESS. dag_id=trabalho2, task_id=also_run_this, execution_date=20221013T220403, start_date=20221013T220405, end_date=20221013T220410
[2022-10-13T22:04:10.278+0000] {local_task_job.py:164} INFO - Task exited with return code 0
[2022-10-13T22:04:10.307+0000] {local_task_job.py:273} INFO - 1 downstream tasks scheduled from follow-on schedule check
